[2023-04-02 18:01:12,236] {taskinstance.py:1159} INFO - Dependencies all met for <TaskInstance: user_processing.create_table manual__2023-04-02T18:01:10.363807+00:00 [queued]>
[2023-04-02 18:01:12,249] {taskinstance.py:1159} INFO - Dependencies all met for <TaskInstance: user_processing.create_table manual__2023-04-02T18:01:10.363807+00:00 [queued]>
[2023-04-02 18:01:12,250] {taskinstance.py:1356} INFO - 
--------------------------------------------------------------------------------
[2023-04-02 18:01:12,251] {taskinstance.py:1357} INFO - Starting attempt 1 of 1
[2023-04-02 18:01:12,252] {taskinstance.py:1358} INFO - 
--------------------------------------------------------------------------------
[2023-04-02 18:01:12,266] {taskinstance.py:1377} INFO - Executing <Task(PostgresOperator): create_table> on 2023-04-02 18:01:10.363807+00:00
[2023-04-02 18:01:12,273] {standard_task_runner.py:52} INFO - Started process 340 to run task
[2023-04-02 18:01:12,277] {standard_task_runner.py:79} INFO - Running: ['***', 'tasks', 'run', 'user_processing', 'create_table', 'manual__2023-04-02T18:01:10.363807+00:00', '--job-id', '3', '--raw', '--subdir', 'DAGS_FOLDER/user_processing.py', '--cfg-path', '/tmp/tmppd2yobm3', '--error-file', '/tmp/tmpei4t3du1']
[2023-04-02 18:01:12,279] {standard_task_runner.py:80} INFO - Job 3: Subtask create_table
[2023-04-02 18:01:12,342] {task_command.py:369} INFO - Running <TaskInstance: user_processing.create_table manual__2023-04-02T18:01:10.363807+00:00 [running]> on host e18fbfc31089
[2023-04-02 18:01:12,413] {taskinstance.py:1571} INFO - Exporting the following env vars:
AIRFLOW_CTX_DAG_OWNER=***
AIRFLOW_CTX_DAG_ID=user_processing
AIRFLOW_CTX_TASK_ID=create_table
AIRFLOW_CTX_EXECUTION_DATE=2023-04-02T18:01:10.363807+00:00
AIRFLOW_CTX_TRY_NUMBER=1
AIRFLOW_CTX_DAG_RUN_ID=manual__2023-04-02T18:01:10.363807+00:00
[2023-04-02 18:01:12,436] {taskinstance.py:1889} ERROR - Task failed with exception
Traceback (most recent call last):
  File "/home/airflow/.local/lib/python3.7/site-packages/airflow/providers/postgres/operators/postgres.py", line 92, in execute
    self.hook.run(self.sql, self.autocommit, parameters=self.parameters)
  File "/home/airflow/.local/lib/python3.7/site-packages/airflow/hooks/dbapi.py", line 181, in run
    with closing(self.get_conn()) as conn:
  File "/home/airflow/.local/lib/python3.7/site-packages/airflow/providers/postgres/hooks/postgres.py", line 86, in get_conn
    conn = deepcopy(self.connection or self.get_connection(conn_id))
  File "/home/airflow/.local/lib/python3.7/site-packages/airflow/hooks/base.py", line 67, in get_connection
    conn = Connection.get_connection_from_secrets(conn_id)
  File "/home/airflow/.local/lib/python3.7/site-packages/airflow/models/connection.py", line 430, in get_connection_from_secrets
    raise AirflowNotFoundException(f"The conn_id `{conn_id}` isn't defined")
airflow.exceptions.AirflowNotFoundException: The conn_id `postgres` isn't defined
[2023-04-02 18:01:12,441] {taskinstance.py:1400} INFO - Marking task as FAILED. dag_id=user_processing, task_id=create_table, execution_date=20230402T180110, start_date=20230402T180112, end_date=20230402T180112
[2023-04-02 18:01:12,451] {standard_task_runner.py:97} ERROR - Failed to execute job 3 for task create_table (The conn_id `postgres` isn't defined; 340)
[2023-04-02 18:01:12,491] {local_task_job.py:156} INFO - Task exited with return code 1
[2023-04-02 18:01:12,534] {local_task_job.py:273} INFO - 0 downstream tasks scheduled from follow-on schedule check
