[2023-04-02 18:01:12,232] {taskinstance.py:1159} INFO - Dependencies all met for <TaskInstance: user_processing.create_table scheduled__2023-04-01T00:00:00+00:00 [queued]>
[2023-04-02 18:01:12,243] {taskinstance.py:1159} INFO - Dependencies all met for <TaskInstance: user_processing.create_table scheduled__2023-04-01T00:00:00+00:00 [queued]>
[2023-04-02 18:01:12,245] {taskinstance.py:1356} INFO - 
--------------------------------------------------------------------------------
[2023-04-02 18:01:12,246] {taskinstance.py:1357} INFO - Starting attempt 1 of 1
[2023-04-02 18:01:12,247] {taskinstance.py:1358} INFO - 
--------------------------------------------------------------------------------
[2023-04-02 18:01:12,261] {taskinstance.py:1377} INFO - Executing <Task(PostgresOperator): create_table> on 2023-04-01 00:00:00+00:00
[2023-04-02 18:01:12,268] {standard_task_runner.py:52} INFO - Started process 339 to run task
[2023-04-02 18:01:12,272] {standard_task_runner.py:79} INFO - Running: ['***', 'tasks', 'run', 'user_processing', 'create_table', 'scheduled__2023-04-01T00:00:00+00:00', '--job-id', '4', '--raw', '--subdir', 'DAGS_FOLDER/user_processing.py', '--cfg-path', '/tmp/tmpr2j14v4w', '--error-file', '/tmp/tmp_drajo6p']
[2023-04-02 18:01:12,274] {standard_task_runner.py:80} INFO - Job 4: Subtask create_table
[2023-04-02 18:01:12,341] {task_command.py:369} INFO - Running <TaskInstance: user_processing.create_table scheduled__2023-04-01T00:00:00+00:00 [running]> on host e18fbfc31089
[2023-04-02 18:01:12,413] {taskinstance.py:1571} INFO - Exporting the following env vars:
AIRFLOW_CTX_DAG_OWNER=***
AIRFLOW_CTX_DAG_ID=user_processing
AIRFLOW_CTX_TASK_ID=create_table
AIRFLOW_CTX_EXECUTION_DATE=2023-04-01T00:00:00+00:00
AIRFLOW_CTX_TRY_NUMBER=1
AIRFLOW_CTX_DAG_RUN_ID=scheduled__2023-04-01T00:00:00+00:00
[2023-04-02 18:01:12,436] {taskinstance.py:1889} ERROR - Task failed with exception
Traceback (most recent call last):
  File "/home/airflow/.local/lib/python3.7/site-packages/airflow/providers/postgres/operators/postgres.py", line 92, in execute
    self.hook.run(self.sql, self.autocommit, parameters=self.parameters)
  File "/home/airflow/.local/lib/python3.7/site-packages/airflow/hooks/dbapi.py", line 181, in run
    with closing(self.get_conn()) as conn:
  File "/home/airflow/.local/lib/python3.7/site-packages/airflow/providers/postgres/hooks/postgres.py", line 86, in get_conn
    conn = deepcopy(self.connection or self.get_connection(conn_id))
  File "/home/airflow/.local/lib/python3.7/site-packages/airflow/hooks/base.py", line 67, in get_connection
    conn = Connection.get_connection_from_secrets(conn_id)
  File "/home/airflow/.local/lib/python3.7/site-packages/airflow/models/connection.py", line 430, in get_connection_from_secrets
    raise AirflowNotFoundException(f"The conn_id `{conn_id}` isn't defined")
airflow.exceptions.AirflowNotFoundException: The conn_id `postgres` isn't defined
[2023-04-02 18:01:12,441] {taskinstance.py:1400} INFO - Marking task as FAILED. dag_id=user_processing, task_id=create_table, execution_date=20230401T000000, start_date=20230402T180112, end_date=20230402T180112
[2023-04-02 18:01:12,451] {standard_task_runner.py:97} ERROR - Failed to execute job 4 for task create_table (The conn_id `postgres` isn't defined; 339)
[2023-04-02 18:01:12,486] {local_task_job.py:156} INFO - Task exited with return code 1
[2023-04-02 18:01:12,530] {local_task_job.py:273} INFO - 0 downstream tasks scheduled from follow-on schedule check
